Global seed set to 42
GPU available: True (mps), used: False
TPU available: False, using: 0 TPU cores
IPU available: False, using: 0 IPUs
HPU available: False, using: 0 HPUs
/Users/kilianhaefeli/miniconda3/envs/pytorch_lightning_template/lib/python3.11/site-packages/lightning/pytorch/trainer/setup.py:201: UserWarning: MPS available but not used. Set `accelerator` and `devices` using `Trainer(accelerator='mps', devices=1)`.
  rank_zero_warn(
/Users/kilianhaefeli/miniconda3/envs/pytorch_lightning_template/lib/python3.11/site-packages/lightning/pytorch/callbacks/model_checkpoint.py:615: UserWarning: Checkpoint directory /Users/kilianhaefeli/pytorch_lightning_template/outputs/Points_MLP_offset_10_Tm_0.3_seed_42_contours_True_out_type_polar_graph_True_in_type_t_angle_emb_dim_64_num_layer_3_norm_BatchNorm_seed_42_max_epochs_50_batch_size_32_optimizer_NADAM_loss_type_L2_weight_decay_0/checkpoints exists and is not empty.
  rank_zero_warn(f"Checkpoint directory {dirpath} exists and is not empty.")
Restoring states from the checkpoint path at /Users/kilianhaefeli/pytorch_lightning_template/outputs/Points_MLP_offset_10_Tm_0.3_seed_42_contours_True_out_type_polar_graph_True_in_type_t_angle_emb_dim_64_num_layer_3_norm_BatchNorm_seed_42_max_epochs_50_batch_size_32_optimizer_NADAM_loss_type_L2_weight_decay_0/checkpoints/last.ckpt
  | Name | Type | Params
------------------------------
0 | net  | MLP  | 8.5 K
------------------------------
8.5 K     Trainable params
0         Non-trainable params
8.5 K     Total params
0.034     Total estimated model params size (MB)
Restored all states from the checkpoint at /Users/kilianhaefeli/pytorch_lightning_template/outputs/Points_MLP_offset_10_Tm_0.3_seed_42_contours_True_out_type_polar_graph_True_in_type_t_angle_emb_dim_64_num_layer_3_norm_BatchNorm_seed_42_max_epochs_50_batch_size_32_optimizer_NADAM_loss_type_L2_weight_decay_0/checkpoints/last.ckpt
Traceback (most recent call last):
  File "<string>", line 1, in <module>
  File "/Users/kilianhaefeli/miniconda3/envs/pytorch_lightning_template/lib/python3.11/multiprocessing/spawn.py", line 120, in spawn_main
    exitcode = _main(fd, parent_sentinel)
               ^^^^^^^^^^^^^^^^^^^^^^^^^^
  File "/Users/kilianhaefeli/miniconda3/envs/pytorch_lightning_template/lib/python3.11/multiprocessing/spawn.py", line 129, in _main
    prepare(preparation_data)
  File "/Users/kilianhaefeli/miniconda3/envs/pytorch_lightning_template/lib/python3.11/multiprocessing/spawn.py", line 240, in prepare
    _fixup_main_from_path(data['init_main_from_path'])
  File "/Users/kilianhaefeli/miniconda3/envs/pytorch_lightning_template/lib/python3.11/multiprocessing/spawn.py", line 291, in _fixup_main_from_path
    main_content = runpy.run_path(main_path,
                   ^^^^^^^^^^^^^^^^^^^^^^^^^
  File "<frozen runpy>", line 291, in run_path
  File "<frozen runpy>", line 98, in _run_module_code
  File "<frozen runpy>", line 88, in _run_code
  File "/Users/kilianhaefeli/pytorch_lightning_template/test.py", line 1, in <module>
    from experiment import train_Points_MLP
  File "/Users/kilianhaefeli/pytorch_lightning_template/experiment/train_Points_MLP.py", line 39, in <module>
    trainer.train()
  File "/Users/kilianhaefeli/pytorch_lightning_template/project/train.py", line 145, in train
    self.trainer.fit(self.model, self.train_loader, self.validation_loader, ckpt_path = "last")
  File "/Users/kilianhaefeli/miniconda3/envs/pytorch_lightning_template/lib/python3.11/site-packages/lightning/pytorch/trainer/trainer.py", line 531, in fit
    call._call_and_handle_interrupt(
  File "/Users/kilianhaefeli/miniconda3/envs/pytorch_lightning_template/lib/python3.11/site-packages/lightning/pytorch/trainer/call.py", line 42, in _call_and_handle_interrupt
    return trainer_fn(*args, **kwargs)
           ^^^^^^^^^^^^^^^^^^^^^^^^^^^
  File "/Users/kilianhaefeli/miniconda3/envs/pytorch_lightning_template/lib/python3.11/site-packages/lightning/pytorch/trainer/trainer.py", line 570, in _fit_impl
    self._run(model, ckpt_path=ckpt_path)
  File "/Users/kilianhaefeli/miniconda3/envs/pytorch_lightning_template/lib/python3.11/site-packages/lightning/pytorch/trainer/trainer.py", line 975, in _run
    results = self._run_stage()
              ^^^^^^^^^^^^^^^^^
  File "/Users/kilianhaefeli/miniconda3/envs/pytorch_lightning_template/lib/python3.11/site-packages/lightning/pytorch/trainer/trainer.py", line 1016, in _run_stage
    self._run_sanity_check()
  File "/Users/kilianhaefeli/miniconda3/envs/pytorch_lightning_template/lib/python3.11/site-packages/lightning/pytorch/trainer/trainer.py", line 1045, in _run_sanity_check
    val_loop.run()
  File "/Users/kilianhaefeli/miniconda3/envs/pytorch_lightning_template/lib/python3.11/site-packages/lightning/pytorch/loops/utilities.py", line 177, in _decorator
    return loop_run(self, *args, **kwargs)
           ^^^^^^^^^^^^^^^^^^^^^^^^^^^^^^^
  File "/Users/kilianhaefeli/miniconda3/envs/pytorch_lightning_template/lib/python3.11/site-packages/lightning/pytorch/loops/evaluation_loop.py", line 98, in run
    self.setup_data()
  File "/Users/kilianhaefeli/miniconda3/envs/pytorch_lightning_template/lib/python3.11/site-packages/lightning/pytorch/loops/evaluation_loop.py", line 168, in setup_data
    _check_dataloader_iterable(dl, source, trainer_fn)
  File "/Users/kilianhaefeli/miniconda3/envs/pytorch_lightning_template/lib/python3.11/site-packages/lightning/pytorch/trainer/connectors/data_connector.py", line 385, in _check_dataloader_iterable
    iter(dataloader)  # type: ignore[call-overload]
    ^^^^^^^^^^^^^^^^
  File "/Users/kilianhaefeli/miniconda3/envs/pytorch_lightning_template/lib/python3.11/site-packages/torch/utils/data/dataloader.py", line 441, in __iter__
    return self._get_iterator()
           ^^^^^^^^^^^^^^^^^^^^
  File "/Users/kilianhaefeli/miniconda3/envs/pytorch_lightning_template/lib/python3.11/site-packages/torch/utils/data/dataloader.py", line 388, in _get_iterator
    return _MultiProcessingDataLoaderIter(self)
           ^^^^^^^^^^^^^^^^^^^^^^^^^^^^^^^^^^^^
  File "/Users/kilianhaefeli/miniconda3/envs/pytorch_lightning_template/lib/python3.11/site-packages/torch/utils/data/dataloader.py", line 1042, in __init__
    w.start()
  File "/Users/kilianhaefeli/miniconda3/envs/pytorch_lightning_template/lib/python3.11/multiprocessing/process.py", line 121, in start
    self._popen = self._Popen(self)
                  ^^^^^^^^^^^^^^^^^
  File "/Users/kilianhaefeli/miniconda3/envs/pytorch_lightning_template/lib/python3.11/multiprocessing/context.py", line 224, in _Popen
    return _default_context.get_context().Process._Popen(process_obj)
           ^^^^^^^^^^^^^^^^^^^^^^^^^^^^^^^^^^^^^^^^^^^^^^^^^^^^^^^^^^
  File "/Users/kilianhaefeli/miniconda3/envs/pytorch_lightning_template/lib/python3.11/multiprocessing/context.py", line 288, in _Popen
    return Popen(process_obj)
           ^^^^^^^^^^^^^^^^^^
  File "/Users/kilianhaefeli/miniconda3/envs/pytorch_lightning_template/lib/python3.11/multiprocessing/popen_spawn_posix.py", line 32, in __init__
    super().__init__(process_obj)
  File "/Users/kilianhaefeli/miniconda3/envs/pytorch_lightning_template/lib/python3.11/multiprocessing/popen_fork.py", line 19, in __init__
    self._launch(process_obj)
  File "/Users/kilianhaefeli/miniconda3/envs/pytorch_lightning_template/lib/python3.11/multiprocessing/popen_spawn_posix.py", line 42, in _launch
    prep_data = spawn.get_preparation_data(process_obj._name)
                ^^^^^^^^^^^^^^^^^^^^^^^^^^^^^^^^^^^^^^^^^^^^^
  File "/Users/kilianhaefeli/miniconda3/envs/pytorch_lightning_template/lib/python3.11/multiprocessing/spawn.py", line 158, in get_preparation_data
    _check_not_importing_main()
  File "/Users/kilianhaefeli/miniconda3/envs/pytorch_lightning_template/lib/python3.11/multiprocessing/spawn.py", line 138, in _check_not_importing_main
    raise RuntimeError('''
RuntimeError:
        An attempt has been made to start a new process before the
        current process has finished its bootstrapping phase.
        This probably means that you are not using fork to start your
        child processes and you have forgotten to use the proper idiom
        in the main module:
            if __name__ == '__main__':
                freeze_support()
                ...
        The "freeze_support()" line can be omitted if the program
        is not going to be frozen to produce an executable.
Traceback (most recent call last):
  File "/Users/kilianhaefeli/miniconda3/envs/pytorch_lightning_template/lib/python3.11/site-packages/torch/utils/data/dataloader.py", line 1132, in _try_get_data
    data = self._data_queue.get(timeout=timeout)
           ^^^^^^^^^^^^^^^^^^^^^^^^^^^^^^^^^^^^^
  File "/Users/kilianhaefeli/miniconda3/envs/pytorch_lightning_template/lib/python3.11/multiprocessing/queues.py", line 113, in get
    if not self._poll(timeout):
           ^^^^^^^^^^^^^^^^^^^
  File "/Users/kilianhaefeli/miniconda3/envs/pytorch_lightning_template/lib/python3.11/multiprocessing/connection.py", line 256, in poll
    return self._poll(timeout)
           ^^^^^^^^^^^^^^^^^^^
  File "/Users/kilianhaefeli/miniconda3/envs/pytorch_lightning_template/lib/python3.11/multiprocessing/connection.py", line 423, in _poll
    r = wait([self], timeout)
        ^^^^^^^^^^^^^^^^^^^^^
  File "/Users/kilianhaefeli/miniconda3/envs/pytorch_lightning_template/lib/python3.11/multiprocessing/connection.py", line 930, in wait
    ready = selector.select(timeout)
            ^^^^^^^^^^^^^^^^^^^^^^^^
  File "/Users/kilianhaefeli/miniconda3/envs/pytorch_lightning_template/lib/python3.11/selectors.py", line 415, in select
    fd_event_list = self._selector.poll(timeout)
                    ^^^^^^^^^^^^^^^^^^^^^^^^^^^^
  File "/Users/kilianhaefeli/miniconda3/envs/pytorch_lightning_template/lib/python3.11/site-packages/torch/utils/data/_utils/signal_handling.py", line 66, in handler
    _error_if_any_worker_fails()
RuntimeError: DataLoader worker (pid 31632) exited unexpectedly with exit code 1. Details are lost due to multiprocessing. Rerunning with num_workers=0 may give better error trace.
The above exception was the direct cause of the following exception:
Traceback (most recent call last):
  File "/Users/kilianhaefeli/pytorch_lightning_template/test.py", line 1, in <module>
    from experiment import train_Points_MLP
  File "/Users/kilianhaefeli/pytorch_lightning_template/experiment/train_Points_MLP.py", line 39, in <module>
    trainer.train()
  File "/Users/kilianhaefeli/pytorch_lightning_template/project/train.py", line 145, in train
    self.trainer.fit(self.model, self.train_loader, self.validation_loader, ckpt_path = "last")
  File "/Users/kilianhaefeli/miniconda3/envs/pytorch_lightning_template/lib/python3.11/site-packages/lightning/pytorch/trainer/trainer.py", line 531, in fit
    call._call_and_handle_interrupt(
  File "/Users/kilianhaefeli/miniconda3/envs/pytorch_lightning_template/lib/python3.11/site-packages/lightning/pytorch/trainer/call.py", line 42, in _call_and_handle_interrupt
    return trainer_fn(*args, **kwargs)
           ^^^^^^^^^^^^^^^^^^^^^^^^^^^
  File "/Users/kilianhaefeli/miniconda3/envs/pytorch_lightning_template/lib/python3.11/site-packages/lightning/pytorch/trainer/trainer.py", line 570, in _fit_impl
    self._run(model, ckpt_path=ckpt_path)
  File "/Users/kilianhaefeli/miniconda3/envs/pytorch_lightning_template/lib/python3.11/site-packages/lightning/pytorch/trainer/trainer.py", line 975, in _run
    results = self._run_stage()
              ^^^^^^^^^^^^^^^^^
  File "/Users/kilianhaefeli/miniconda3/envs/pytorch_lightning_template/lib/python3.11/site-packages/lightning/pytorch/trainer/trainer.py", line 1016, in _run_stage
    self._run_sanity_check()
  File "/Users/kilianhaefeli/miniconda3/envs/pytorch_lightning_template/lib/python3.11/site-packages/lightning/pytorch/trainer/trainer.py", line 1045, in _run_sanity_check
    val_loop.run()
  File "/Users/kilianhaefeli/miniconda3/envs/pytorch_lightning_template/lib/python3.11/site-packages/lightning/pytorch/loops/utilities.py", line 177, in _decorator
    return loop_run(self, *args, **kwargs)
           ^^^^^^^^^^^^^^^^^^^^^^^^^^^^^^^
  File "/Users/kilianhaefeli/miniconda3/envs/pytorch_lightning_template/lib/python3.11/site-packages/lightning/pytorch/loops/evaluation_loop.py", line 108, in run
    batch, batch_idx, dataloader_idx = next(data_fetcher)
                                       ^^^^^^^^^^^^^^^^^^
  File "/Users/kilianhaefeli/miniconda3/envs/pytorch_lightning_template/lib/python3.11/site-packages/lightning/pytorch/loops/fetchers.py", line 136, in __next__
    self._fetch_next_batch(self.dataloader_iter)
  File "/Users/kilianhaefeli/miniconda3/envs/pytorch_lightning_template/lib/python3.11/site-packages/lightning/pytorch/loops/fetchers.py", line 150, in _fetch_next_batch
    batch = next(iterator)
            ^^^^^^^^^^^^^^
  File "/Users/kilianhaefeli/miniconda3/envs/pytorch_lightning_template/lib/python3.11/site-packages/lightning/pytorch/utilities/combined_loader.py", line 284, in __next__
    out = next(self._iterator)
          ^^^^^^^^^^^^^^^^^^^^
  File "/Users/kilianhaefeli/miniconda3/envs/pytorch_lightning_template/lib/python3.11/site-packages/lightning/pytorch/utilities/combined_loader.py", line 123, in __next__
    out = next(self.iterators[0])
          ^^^^^^^^^^^^^^^^^^^^^^^
  File "/Users/kilianhaefeli/miniconda3/envs/pytorch_lightning_template/lib/python3.11/site-packages/torch/utils/data/dataloader.py", line 633, in __next__
    data = self._next_data()
           ^^^^^^^^^^^^^^^^^
  File "/Users/kilianhaefeli/miniconda3/envs/pytorch_lightning_template/lib/python3.11/site-packages/torch/utils/data/dataloader.py", line 1328, in _next_data
    idx, data = self._get_data()
                ^^^^^^^^^^^^^^^^
  File "/Users/kilianhaefeli/miniconda3/envs/pytorch_lightning_template/lib/python3.11/site-packages/torch/utils/data/dataloader.py", line 1294, in _get_data
    success, data = self._try_get_data()
                    ^^^^^^^^^^^^^^^^^^^^
  File "/Users/kilianhaefeli/miniconda3/envs/pytorch_lightning_template/lib/python3.11/site-packages/torch/utils/data/dataloader.py", line 1145, in _try_get_data
    raise RuntimeError('DataLoader worker (pid(s) {}) exited unexpectedly'.format(pids_str)) from e
RuntimeError: DataLoader worker (pid(s) 31632) exited unexpectedly
Sanity Checking: 0it [00:00, ?it/s]